Workbook

Sheet Portada
E6: Plan de prueba software Hilo
E35: Integrantes: Dayana Hoyos - Yhonneider Vivas

Sheet Plan de prueba
G1: ID | H1: Nombre de la prueba | I1: Tipo | J1: Resultado esperado | K1: Pre condicion | L1: Resultado obtenido | M1: Datos de prueba | N1: Modulo a probar | O1: Criterios de aceptacion | P1: Estrategia | Q1: Resultado | R1: Candidato a automatizar | S1: Responsable ejecución
E2: MTC | F2: 10 | G2: =E2&"_00"&F2 -> MTC_0010 | H2: HU-01 - Registrar cuenta con correo y contraseña válidos | I2: Funcional | J2: La cuenta se crea correctamente y el lector puede continuar con su inicio de sesión. | K2: El lector no posee una cuenta y se encuentra en la pantalla de registro. | L2: La cuenta se crea correctamente y se redirige al módulo de inicio de sesión. | M2: correo: lector1@hilo.test; contraseña: ClaveSegura123! | N2: Autenticación | O2: HU-01: se permite crear una cuenta con correo válido y contraseña que cumple los requisitos. | P2: Caja Negra | Q2: OK | R2: SI | S2: Dayana Hoyos
E3: MTC | F3: 20 | G3: =E3&"_00"&F3 -> MTC_0020 | H3: HU-01 - Validar formato de correo y requisitos de contraseña | I3: Funcional | J3: El sistema informa los datos inválidos y no crea la cuenta. | K3: El lector se encuentra en la pantalla de registro. | L3: La aplicación informa que el correo y la contraseña no cumplen con los estándares definidos | M3: correo: lector@; contraseña: 123 | N3: Autenticación | O3: HU-01: correo y contraseña deben cumplir las validaciones definidas. | P3: Caja Negra | Q3: OK | R3: SI | S3: Dayana Hoyos
E4: MTC | F4: 30 | G4: =E4&"_00"&F4 -> MTC_0030 | H4: HU-01 - Impedir registro con correo ya utilizado | I4: Funcional | J4: El sistema informa que el correo ya está asociado a una cuenta y no genera un duplicado. | K4: Existe una cuenta registrada con el correo de prueba. | L4: No se permite crear una cuenta de un correo ya registrado | M4: correo: lector1@hilo.test; contraseña: ClaveSegura123! | N4: Autenticación | O4: HU-01: no se debe crear una segunda cuenta con el mismo correo. | P4: Caja Negra | Q4: OK | R4: SI | S4: Dayana Hoyos
E5: MTC | F5: 40 | G5: =E5&"_00"&F5 -> MTC_0040 | H5: HU-02 - Iniciar sesión con correo y contraseña válidos | I5: Funcional | J5: El lector es autenticado y accede a la pantalla principal. | K5: Existe una cuenta registrada y el lector está sin sesión iniciada. | L5: La aplicación permite ingresar a la página de inicio | M5: correo: lector1@hilo.test; contraseña: ClaveSegura123! | N5: Autenticación | O5: HU-02: las credenciales válidas permiten acceder a la cuenta. | P5: Caja Negra | Q5: OK | R5: SI | S5: Dayana Hoyos
E6: MTC | F6: 50 | G6: =E6&"_00"&F6 -> MTC_0050 | H6: HU-02 - Rechazar credenciales incorrectas | I6: Funcional | J6: El sistema informa que las credenciales no son válidas y mantiene al lector en la pantalla de acceso. | K6: Existe una cuenta registrada. | L6: La aplicación no permite ingresar a la cuenta con credenciales inválidas | M6: correo: lector1@hilo.test; contraseña: Incorrecta123! | N6: Autenticación | O6: HU-02: credenciales inválidas no deben iniciar una sesión. | P6: Caja Negra | Q6: OK | R6: SI | S6: Dayana Hoyos
E7: MTC | F7: 60 | G7: =E7&"_00"&F7 -> MTC_0060 | H7: HU-02 - Validar campos obligatorios de inicio de sesión | I7: Funcional | J7: El sistema solicita completar los campos obligatorios y no intenta autenticar. | K7: El lector se encuentra en la pantalla de acceso. | L7: Se solicitan todos los campos para iniciar sesión | M7: correo vacío; contraseña vacía | N7: Autenticación | O7: HU-02: correo y contraseña son obligatorios. | P7: Caja Negra | Q7: OK | R7: SI | S7: Dayana Hoyos
E8: MTC | F8: 70 | G8: =E8&"_00"&F8 -> MTC_0070 | H8: HU-03 - Cerrar sesión | I8: Funcional | J8: La sesión finaliza y el lector vuelve a la pantalla de acceso. | K8: El lector tiene una sesión válida iniciada. | L8: La sesión se cierra exitosamente | M8: usuario autenticado | N8: Autenticación | O8: HU-03: el lector puede cerrar su sesión actual. | P8: Caja Negra | Q8: OK | R8: SI | S8: Dayana Hoyos
E9: MTC | F9: 80 | G9: =E9&"_00"&F9 -> MTC_0080 | H9: HU-04 - Confirmar eliminación de cuenta | I9: Funcional | J9: La cuenta se elimina y el lector deja de tener acceso a la sesión y a sus datos asociados. | K9: El lector está autenticado y solicita eliminar su cuenta. | M9: usuario de prueba con biblioteca y citas | N9: Autenticación | O9: HU-04: la eliminación confirmada debe completar el proceso y cerrar la sesión. | P9: Caja Negra | Q9: No ejecutado | R9: NO
E10: MTC | F10: 90 | G10: =E10&"_00"&F10 -> MTC_0090 | H10: HU-04 - Cancelar eliminación de cuenta | I10: Funcional | J10: La cuenta permanece activa y no se elimina información. | K10: El lector está autenticado y abre la opción para eliminar su cuenta. | M10: usuario de prueba | N10: Autenticación | O10: HU-04: cancelar la confirmación no debe eliminar la cuenta. | P10: Caja Negra | Q10: No ejecutado | R10: NO
E11: MTC | F11: 100 | G11: =E11&"_00"&F11 -> MTC_00100 | H11: HU-05 - Crear perfil con datos válidos | I11: Funcional | J11: El perfil se guarda y puede visualizarse con el nombre y nombre de usuario ingresados. | K11: El lector acaba de registrarse y aún no tiene perfil configurado. | L11: El nombre y nombre de usuario quedan guardados y se visualizan exitosamente | M11: nombre: Lector Uno; username: lectoruno | N11: Perfil | O11: HU-05: el lector puede crear su perfil con información válida. | P11: Caja Negra | Q11: OK | R11: SI | S11: Dayana Hoyos
E12: MTC | F12: 110 | G12: =E12&"_00"&F12 -> MTC_00110 | H12: HU-05 - Crear perfil sin fotografía | I12: Funcional | J12: El perfil se crea correctamente utilizando la presentación visual por defecto. | K12: El lector está configurando su perfil por primera vez. | L12: El perfil se crea correctamente sin fotografía | M12: nombre: Lector Uno; username: lectoruno; fotografía: sin seleccionar | N12: Perfil | O12: HU-05: la fotografía de perfil es opcional. | P12: Caja Negra | Q12: OK | R12: SI | S12: Dayana Hoyos
E13: MTC | F13: 120 | G13: =E13&"_00"&F13 -> MTC_00120 | H13: HU-06 - Visualizar perfil propio | I13: Funcional | J13: Se muestran correctamente los datos del perfil y la información disponible del lector. | K13: El lector está autenticado y posee un perfil. | L13: Al consultar el perfil se visualizan los datos correctamente | M13: perfil de lector1 | N13: Perfil | O13: HU-06: el lector puede consultar la información de su propio perfil. | P13: Caja Negra | Q13: OK | R13: SI | S13: Dayana Hoyos
E14: MTC | F14: 130 | G14: =E14&"_00"&F14 -> MTC_00130 | H14: HU-07 - Editar nombre y nombre de usuario | I14: Funcional | J14: Los cambios se guardan y aparecen inmediatamente en el perfil. | K14: El lector está autenticado y posee un perfil. | L14: Al editar el nombre y nombre de usuario, los cambios se actualizan | M14: nombre nuevo: Lector Actualizado; username: lectoractualizado | N14: Perfil | O14: HU-07: los datos editables del perfil pueden modificarse y persistir. | P14: Caja Negra | Q14: OK | R14: SI | S14: Dayana Hoyos
E15: MTC | F15: 140 | G15: =E15&"_00"&F15 -> MTC_00140 | H15: HU-07 - Cambiar fotografía de perfil | I15: Funcional | J15: La nueva fotografía se carga, guarda y se muestra en el perfil. | K15: El lector está autenticado y posee un perfil. | L15: Al cambiar una fotografía en el perfil desde la galería, se guarda y se muestra en el perfil | M15: imagen JPG/PNG válida desde la galería | N15: Perfil | O15: HU-07: el lector puede cambiar su fotografía de perfil. | P15: Caja Negra | Q15: OK | R15: NO | S15: Dayana Hoyos
E16: MTC | F16: 150 | G16: =E16&"_00"&F16 -> MTC_00150 | H16: HU-08 - Visualizar estadísticas básicas | I16: Funcional | J16: Se muestran estadísticas calculadas a partir de la actividad y biblioteca del lector. | K16: El lector está autenticado y posee datos de lectura registrados. | L16: En el perfil se muestran estadísticas básicas de libros leídos, por leer, etc | M16: usuario con libros leídos y en lectura | N16: Perfil | O16: HU-08: el perfil debe mostrar las estadísticas básicas disponibles. | P16: Caja Negra | Q16: OK | R16: SI | S16: Dayana Hoyos
E17: MTC | F17: 160 | G17: =E17&"_00"&F17 -> MTC_00160 | H17: HU-09 - Buscar libros con término válido | I17: Funcional | J17: La aplicación muestra una lista de libros relacionados con la búsqueda. | K17: El lector está autenticado y dispone de conexión. | L17: La aplicación muestra la lista de libros coincidientes con la búsqueda | M17: búsqueda: La metamorfosis | N17: Búsqueda | O17: HU-09: la búsqueda por título, autor o palabra clave debe devolver resultados relacionados. | P17: Caja Negra | Q17: OK | R17: SI | S17: Dayana Hoyos
E18: MTC | F18: 170 | G18: =E18&"_00"&F18 -> MTC_00170 | H18: HU-09 - Buscar término sin resultados | I18: Funcional | J18: La aplicación informa que no se encontraron resultados sin producir errores. | K18: El lector está autenticado y dispone de conexión. | L18: La aplicación muestra libros que no corresponden | M18: búsqueda: zzlibroinexistentezz | N18: Búsqueda | O18: HU-09: una búsqueda sin coincidencias debe manejarse correctamente. | P18: Caja Negra | Q18: NOK | R18: SI | S18: Dayana Hoyos
E19: MTC | F19: 180 | G19: =E19&"_00"&F19 -> MTC_00180 | H19: HU-10 - Visualizar detalle de un libro | I19: Funcional | J19: Se muestran los datos bibliográficos disponibles del libro seleccionado y los campos opcionales ausentes no rompen la vista. | K19: Existe al menos un resultado de búsqueda. | L19: Se muestran los datos disponibles del libro seleccionado | M19: libro con título, autores y portada; campos opcionales variables | N19: Búsqueda | O19: HU-10: el lector puede consultar el detalle disponible de un libro. | P19: Caja Negra | Q19: OK | R19: SI | S19: Dayana Hoyos
E20: MTC | F20: 190 | G20: =E20&"_00"&F20 -> MTC_00190 | H20: HU-11 - Agregar libro a la biblioteca | I20: Funcional | J20: El libro se guarda en la biblioteca con el estado seleccionado. | K20: El lector está autenticado y visualiza el detalle de un libro que aún no está en su biblioteca. | L20: El libro seleccionado se guarda en la biblioteca con estado Por leer | M20: estado: Por leer | N20: Biblioteca | O20: HU-11: el lector puede agregar un libro seleccionando un estado de lectura. | P20: Caja Negra | Q20: OK | R20: SI | S20: Dayana Hoyos
E21: MTC | F21: 200 | G21: =E21&"_00"&F21 -> MTC_00200 | H21: HU-11 - Conservar libro agregado al volver a abrir la aplicación | I21: Funcional | J21: El libro continúa disponible en la biblioteca con el estado seleccionado. | K21: Se agregó previamente un libro a la biblioteca. | L21: Se cierra la aplicación y se abre nuevamente, el libro continúa en la biblioteca con su estado | M21: libro agregado: La metamorfosis | N21: Biblioteca | O21: HU-11: el libro agregado debe persistir en la biblioteca. | P21: Caja Negra | Q21: OK | R21: SI | S21: Dayana Hoyos
E22: MTC | F22: 210 | G22: =E22&"_00"&F22 -> MTC_00210 | H22: HU-12 - Visualizar biblioteca organizada por estado | I22: Funcional | J22: Los libros se muestran en las secciones correspondientes a Por leer, Leyendo y Leído. | K22: El lector posee libros registrados en distintos estados. | L22: Los libros se muestran en secciones separadas según su estado | M22: biblioteca con libros en los tres estados | N22: Biblioteca | O22: HU-12: la biblioteca debe organizar los libros según su estado de lectura. | P22: Caja Negra | Q22: OK | R22: SI | S22: Dayana Hoyos
E23: MTC | F23: 220 | G23: =E23&"_00"&F23 -> MTC_00220 | H23: HU-13 - Cambiar estado de un libro | I23: Funcional | J23: El nuevo estado se guarda y el libro aparece en la sección correspondiente. | K23: El libro ya pertenece a la biblioteca. | L23: El estado del libro se actualiza correctamente | M23: cambio: Por leer -> Leyendo | N23: Biblioteca | O23: HU-13: el lector puede cambiar un libro entre los estados disponibles. | P23: Caja Negra | Q23: OK | R23: SI | S23: Dayana Hoyos
E24: MTC | F24: 230 | G24: =E24&"_00"&F24 -> MTC_00230 | H24: HU-14 - Registrar fecha de inicio de lectura | I24: Funcional | J24: La fecha de inicio queda asociada al libro cuando comienza la lectura. | K24: El libro pertenece a la biblioteca. | M24: estado: Leyendo; fecha de inicio: fecha actual | N24: Biblioteca | O24: HU-14: se conserva la fecha de inicio cuando corresponda. | P24: Caja Negra | Q24: No ejecutado | R24: SI
E25: MTC | F25: 240 | G25: =E25&"_00"&F25 -> MTC_00240 | H25: HU-14 - Registrar fecha de término de lectura | I25: Funcional | J25: La fecha de término queda asociada al libro al marcarlo como leído. | K25: El libro se encuentra en estado Leyendo. | L25: La fecha de término queda asociada a la fecha en la que el libro cambia de estado a Léido | M25: estado nuevo: Leído; fecha de término: fecha actual | N25: Biblioteca | O25: HU-14: se conserva la fecha de término cuando corresponda. | P25: Caja Negra | Q25: OK | R25: SI | S25: Dayana Hoyos
E26: MTC | F26: 250 | G26: =E26&"_00"&F26 -> MTC_00250 | H26: HU-15 - Consultar historial de libros terminados | I26: Funcional | J26: Se muestran los libros finalizados por el lector con la información disponible. | K26: El lector posee al menos un libro marcado como Leído. | L26: Se muestran los libros leídos | M26: usuario con libros terminados | N26: Biblioteca | O26: HU-15: el lector puede consultar su historial de libros terminados. | P26: Caja Negra | Q26: OK | R26: SI | S26: Dayana Hoyos
E27: MTC | F27: 260 | G27: =E27&"_00"&F27 -> MTC_00260 | H27: HU-16 - Registrar página actual válida | I27: Funcional | J27: La página actual se guarda y queda reflejada en el detalle del libro. | K27: El libro está en estado Leyendo y tiene un total de páginas conocido. | L27: La página ingresada se guarda y queda reflejada en el libro | M27: página actual: 50; total: 1040 | N27: Seguimiento | O27: HU-16: una página válida debe actualizar el progreso. | P27: Caja Negra | Q27: OK | R27: SI | S27: Dayana Hoyos
E28: MTC | F28: 270 | G28: =E28&"_00"&F28 -> MTC_00270 | H28: HU-16 - Rechazar página fuera del rango | I28: Funcional | J28: El sistema no guarda el valor e informa la validación correspondiente. | K28: El libro está en estado Leyendo y tiene 1040 páginas. | L28: Se visualiza un error al ingresar un número de página mayor al que tiene el libro | M28: página actual: 2000 | N28: Seguimiento | O28: HU-16: la página no puede ser menor a 1 ni superar el total del libro. | P28: Caja Negra | Q28: OK | R28: SI | S28: Dayana Hoyos
E29: MTC | F29: 280 | G29: =E29&"_00"&F29 -> MTC_00280 | H29: HU-17 - Calcular porcentaje de lectura | I29: Funcional | J29: El porcentaje mostrado corresponde a la relación entre página actual y total de páginas. | K29: El libro tiene total de páginas y progreso registrado. | L29: El porcentaje mostrado es correcto | M29: página actual: 50; total: 1040; esperado: 4% | N29: Seguimiento | O29: HU-17: el porcentaje se calcula automáticamente cuando existen datos suficientes. | P29: Caja Negra | Q29: OK | R29: SI | S29: Dayana Hoyos
E30: MTC | F30: 290 | G30: =E30&"_00"&F30 -> MTC_00290 | H30: HU-18 - Acceder a libros que se están leyendo | I30: Funcional | J30: La aplicación muestra los libros en estado Leyendo y permite entrar a su seguimiento. | K30: El lector posee al menos un libro en estado Leyendo. | L30: Se muestran los libros en estado Leyendo y se puede ingresar a cada uno | M30: biblioteca con 2 libros en lectura | N30: Seguimiento | O30: HU-18: los libros en lectura deben ser accesibles para continuar el seguimiento. | P30: Caja Negra | Q30: OK | R30: SI | S30: Dayana Hoyos
E31: MTC | F31: 300 | G31: =E31&"_00"&F31 -> MTC_00300 | H31: HU-19 - Visualizar calendario mensual de lectura | I31: Funcional | J31: Se muestra el mes correspondiente y se identifican los días con actividad registrada. | K31: El lector posee actividad de lectura registrada. | M31: actividad distribuida en distintos días del mes | N31: Calendario | O31: HU-19: el lector puede consultar su actividad en un calendario mensual. | P31: Caja Negra | Q31: No ejecutado | R31: SI
E32: MTC | F32: 310 | G32: =E32&"_00"&F32 -> MTC_00310 | H32: HU-20 - Registrar actividad en calendario al actualizar progreso | I32: Funcional | J32: El día de la actualización queda reflejado automáticamente como actividad de lectura. | K32: El libro está en estado Leyendo. | M32: actualización de página 20 a 35 | N32: Calendario | O32: HU-20: actualizar el progreso debe generar actividad en la fecha correspondiente. | P32: Caja Negra | Q32: No ejecutado | R32: SI
E33: MTC | F33: 320 | G33: =E33&"_00"&F33 -> MTC_00320 | H33: HU-21 - Consultar libros asociados a un día del calendario | I33: Funcional | J33: Se muestran los libros relacionados con la actividad registrada en el día seleccionado. | K33: Existe actividad de lectura en el día seleccionado. | M33: día con actividad de 1 o más libros | N33: Calendario | O33: HU-21: seleccionar un día permite consultar sus libros asociados. | P33: Caja Negra | Q33: No ejecutado | R33: SI
E34: MTC | F34: 330 | G34: =E34&"_00"&F34 -> MTC_00330 | H34: HU-22 - Navegar entre meses del calendario | I34: Funcional | J34: El calendario cambia al mes anterior o siguiente y muestra la actividad correspondiente. | K34: El lector se encuentra en la vista de calendario. | M34: navegar al mes anterior y al siguiente | N34: Calendario | O34: HU-22: el lector puede navegar entre distintos meses. | P34: Caja Negra | Q34: No ejecutado | R34: SI
E35: MTC | F35: 340 | G35: =E35&"_00"&F35 -> MTC_00340 | H35: HU-23 - Guardar cita escrita manualmente | I35: Funcional | J35: La cita se guarda asociada al libro y aparece en la lista de citas. | K35: El lector está autenticado y posee un libro en su biblioteca. | L35: Se puede guardar una cita ingresada manualmente y aparece en la lista de citas | M35: texto: Texto de cita de prueba; página: 45 | N35: Citas | O35: HU-23: una cita manual con contenido válido puede guardarse. | P35: Caja Negra | Q35: OK | R35: SI | S35: Dayana Hoyos
E36: MTC | F36: 350 | G36: =E36&"_00"&F36 -> MTC_00350 | H36: HU-23 - Impedir guardar cita manual vacía | I36: Funcional | J36: La aplicación no guarda la cita y mantiene deshabilitada la acción o informa la validación. | K36: El lector está creando una cita manual. | L36: No es posible guardar una cita vacía porque mantiene deshabilitada la opción de guardar | M36: texto vacío o solo espacios | N36: Citas | O36: HU-23: el contenido de una cita no puede estar vacío. | P36: Caja Negra | Q36: OK | R36: SI | S36: Dayana Hoyos
E37: MTC | F37: 360 | G37: =E37&"_00"&F37 -> MTC_00360 | H37: HU-24 - Extraer texto de una cita desde una imagen | I37: Funcional | J37: La aplicación reconoce texto en la imagen y lo presenta para revisión antes de guardar. | K37: El lector dispone de una imagen legible con texto. | L37: Se permite tomar una foto y recortar la parte deseada para extraer texto solo de esa área y se presenta para su revisión y edición | M37: fotografía de una página con una cita legible | N37: Citas | O37: HU-24: el lector puede obtener texto desde una fotografía mediante OCR. | P37: Caja Negra | Q37: OK | R37: NO | S37: Dayana Hoyos
E38: MTC | F38: 370 | G38: =E38&"_00"&F38 -> MTC_00370 | H38: HU-24 - Manejar imagen sin texto reconocible | I38: Funcional | J38: La aplicación informa que no pudo obtener texto utilizable y no se cierra inesperadamente. | K38: El lector accede al flujo de OCR. | L38: Si se toma una foto sin texto entonces se carga la plantilla de la cita vacía, debería haber una validación que avise que no se encontró texto | M38: imagen borrosa o sin texto | N38: Citas | O38: HU-24: un reconocimiento sin resultado debe manejarse sin guardar contenido inválido. | P38: Caja Negra | Q38: NOK | R38: NO | S38: Dayana Hoyos
E39: MTC | F39: 380 | G39: =E39&"_00"&F39 -> MTC_00380 | H39: HU-25 - Editar texto obtenido por OCR antes de guardar | I39: Funcional | J39: El texto corregido se conserva y es el contenido que se guarda en la cita. | K39: El OCR ha generado texto editable. | L39: Se puede editar el texto extraído y se guarda correctamente | M39: texto OCR con error -> texto corregido | N39: Citas | O39: HU-25: el lector puede revisar y corregir el texto reconocido antes de guardarlo. | P39: Caja Negra | Q39: OK | R39: SI | S39: Dayana Hoyos
E40: MTC | F40: 390 | G40: =E40&"_00"&F40 -> MTC_00390 | H40: HU-26 - Asociar cita a un libro | I40: Funcional | J40: La cita queda vinculada al libro seleccionado y se muestra dentro de su contexto. | K40: El lector posee libros en su biblioteca y está creando una cita. | L40: La cita agregada queda asociada al libro seleccionado | M40: libro seleccionado: libro de prueba | N40: Citas | O40: HU-26: una cita puede asociarse a un libro. | P40: Caja Negra | Q40: OK | R40: SI | S40: Dayana Hoyos
...

Sheet Control
B6: Casos | C6: OK | D6: =COUNTIF('Plan de prueba'!Q2:Q97,Control!C6) -> 35
C7: NOK | D7: =COUNTIF('Plan de prueba'!Q2:Q97,Control!C7) -> 5
C8: No ejecutado | D8: =COUNTIF('Plan de prueba'!Q2:Q97,C8) -> 56
C9: Bloqueado | D9: =COUNTIF('Plan de prueba'!Q2:Q97,C9) -> 0
C10: Obsoleto | D10: =COUNTIF('Plan de prueba'!Q2:Q97,C10) -> 0
B13: Total de casos | D13: =COUNTIF('Plan de prueba'!E2:E97,"*") -> 96
B14: % de avance | D14: =SUM(D6+D7+D9+D10)/D13 -> 0.41666667
B18: Total casos que ejecuto cada integrante del equipo | D18: Dayana Hoyos | F18: =COUNTIF('Plan de prueba'!$S$2:$S$97,D18) -> 40
D19: Yhon Vivas | F19: =COUNTIF('Plan de prueba'!$S$2:$S$97,D19) -> 0
D23: Total Casos | F23: =SUM(F18:F21) -> 40

Sheet Datos
A1: Funcional | B1: OK | C1: Baja | D1: SI
A2: No Funcional | B2: NOK | C2: Media | D2: NO
A3: UAT | B3: No ejecutado | C3: Alta
A4: Unitaria | B4: Bloqueado
A5: Integración | B5: Obsoleto
A6: End to End
A7: Rendimiento
A8: Carga
A9: Stress

Sheet Estrategia de pruebas
A1: Estrategia y alcance del Plan de Pruebas
A3: Objetivo
A4: Validar que Hilo cumpla sus historias de usuario, criterios de aceptación y requisitos no funcionales mediante pruebas ejecutadas de forma incremental durante los sprints. El plan incluye pruebas unitarias, de integración, funcionales, de aceptación (UAT), End to End y no funcionales.
A7: Tipos de pruebas considerados
A8: Tipo | B8: Aplicación en Hilo | C8: Estrategia principal | D8: Cantidad planificada
A9: Unitaria | B9: Validación aislada de lógica como cálculo de porcentaje, límites de progreso, validación de citas y manejo de datos opcionales. | C9: Caja Blanca | D9: =COUNTIF('Plan de prueba'!$I$2:$I$97,A9) -> 6
A10: Integración | B10: Comunicación entre la aplicación y Supabase, Google Books, Storage y OCR. | C10: Hibrido | D10: =COUNTIF('Plan de prueba'!$I$2:$I$97,A10) -> 7
A11: Funcional | B11: Validación del comportamiento observable de las funcionalidades asociadas a las historias de usuario. | C11: Caja Negra | D11: =COUNTIF('Plan de prueba'!$I$2:$I$97,A11) -> 63
A12: UAT | B12: Comprobación de que los principales grupos funcionales satisfacen los criterios de aceptación desde la perspectiva del lector. | C12: Caja Negra | D12: =COUNTIF('Plan de prueba'!$I$2:$I$97,A12) -> 7
A13: End to End | B13: Validación de flujos completos que atraviesan varios módulos y servicios. | C13: Caja Negra | D13: =COUNTIF('Plan de prueba'!$I$2:$I$97,A13) -> 6
A14: No Funcional | B14: Validación de seguridad, resiliencia, rendimiento perceptible, integridad e internacionalización. | C14: Caja Negra / Hibrido | D14: =COUNTIF('Plan de prueba'!$I$2:$I$97,A14) -> 7
A16: Metodología y estrategias de testing
A17: Estrategia | B17: Aplicación
A18: Ejecución incremental | B18: Los casos se ejecutan a medida que las funcionalidades se completan en cada sprint y se repiten cuando un cambio puede afectar funcionalidades existentes.
A19: Caja negra | B19: Se valida el comportamiento observable de la aplicación sin depender de la implementación interna.
A20: Caja blanca | B20: Se utiliza en pruebas unitarias para validar lógica interna y reglas de negocio aisladas.
A21: Híbrida | B21: Se utiliza en integración y seguridad cuando se valida tanto el comportamiento visible como la interacción con servicios y políticas del backend.
A22: Valores límite | B22: Se prueban valores como página 1, página total, 0, total + 1, campos vacíos y datos opcionales.
A23: Regresión | B23: Después de correcciones o cambios importantes se vuelven a ejecutar los casos críticos afectados.
A25: Herramientas para ejecución y gestión
A26: Herramienta | B26: Uso en el plan de pruebas
A27: Xcode | B27: Ejecución, depuración y verificación de la aplicación iOS.
A28: Swift Testing / XCTest | B28: Automatización de pruebas unitarias y pruebas que puedan ejecutarse desde el proyecto.
A29: Simulador y dispositivo físico | B29: Pruebas funcionales, visuales, de navegación, notificaciones, cámara y compartición.
A30: Supabase | B30: Verificación de autenticación, persistencia, Storage y políticas Row Level Security.
A31: Google Books API | B31: Pruebas de integración de búsqueda y obtención de información bibliográfica.
A32: Vision / OCR | B32: Pruebas de reconocimiento de texto desde imágenes.
A33: Postman o cliente HTTP equivalente | B33: Pruebas controladas de servicios y acceso al backend, especialmente para seguridad y RLS.
A34: Trello y Excel | B34: Gestión de historias, planificación, seguimiento de casos y registro de resultados.
A35: Git | B35: Control de versiones y trazabilidad de cambios asociados a defectos o correcciones.
